<?xml version="1.0"?>
<robot xmlns:xacro="http://www.ros.org/wiki/xacro"  >

    <xacro:include filename="inertial_macros.xacro"/>

    <material name="white">
        <color rgba="1 1 1 1"/>
    </material>

    <material name="orange">
        <color rgba="1 0.3 1 1"/>
    </material>

    <material name="grey">
        <color rgba="0.5 0.5 0.5 1"/>
    </material>

    <material name="purple">
        <color rgba="0.49 0.21 0.49 1"/>
    </material>

    <material name="blue">
        <color rgba="0.2 0.2 1 1"/>
    </material>

    <material name="black">
        <color rgba="0 0 0 1"/>
    </material>
    <material name="green">
        <color rgba="0 1 0 1"/>
    </material>
    
    
    
    
    
    
    
    <!-- BASE -->
    <link name="base_link">
    </link>
    
    
    
     <!-- BASE footprint SLAM -->
    <joint name="base_footprint_joint" type="fixed">
        <parent link="base_link"/>
        <child link="base_footprint"/>
        <origin xyz="0 0 0" rpy="0 0 ${pi/2}"/>
    </joint>

    <link name="base_footprint">
    </link>
    
    
    
    
    
    <!-- Chassis related to the Base -->
    <joint name="chassis_joint" type ="fixed">
        <parent link="base_link"/>
        <child link="chassis"/>
        <origin xyz="0.045 0 -0.012"/> <!-- décalage xyz entre le référentiel chassis et le référentiel centre des roues -->
    </joint>
    <!-- Chassis size and shape-->
    <link name="chassis">
        <visual>
            <origin xyz="-0.045 0 0.01" rpy="0 0 0"/> <!-- Translation du chassis pour que les roues soient fixé en dessous -->
            <geometry>
                <box size="0.09 0.35 0.005"/> <!-- taille du chassis-->
            </geometry>
            <material name="black"/> <!-- couleur du chassis-->
        </visual>
        <collision>
            <origin xyz="-0.045 0 0.01" rpy="0 0 0"/> <!-- Translation du chassis pour que les roues soient fixé en dessous -->
            <geometry>
                <box size="0.09 0.35 0.005"/> <!-- taille du chassis-->
            </geometry>
        </collision>
        <xacro:inertial_box mass="0.5" x="0.09" y="0.28" z="0.02">
            <origin xyz="0.045 0 0.01" rpy="0 0 0"/>
        </xacro:inertial_box>

    </link>

    <gazebo reference="chassis">
        <material>Gazebo/Black</material>
    </gazebo>
    
    
    
    
    
    <!-- Body -->
    <joint name="body_joint" type="fixed">
        <parent link="base_link"/>
        <child link="body"/>
        <origin xyz="0 0.015 -0.012" rpy="0 0 0"/>
    </joint>

    <link name="body">
        <visual>
            <origin xyz="0 0 0.08" rpy="0 0 0"/> 
            <geometry>
                <box size="0.1 0.1 0.12"/> <!-- taille du corp-->
            </geometry>
            <material name="green"/> <!-- couleur du corp-->
        </visual>
        <collision>
            <origin xyz="0 0 -0.08" rpy="0 0 0"/> 
            <geometry>
                <box size="0.09 0.1 0.12"/> <!-- taille du corp-->
            </geometry>
        </collision>
        <xacro:inertial_box mass="0.2" x="0.09" y="0.09" z="0.12">
            <origin xyz="0 0 -0.08" rpy="0 0 0"/>
        </xacro:inertial_box>

    </link>

    <gazebo reference="body">
        <material>Gazebo/Green</material>
    </gazebo>
    
    
   
    
    <!-- LEFT wheels link-->
    <joint name="left_wheel_joint" type="continuous">
        <parent link="base_link"/>
        <child link="left_wheel"/>
        <origin xyz="0 0.205 0.02" rpy="-${pi/2} 0 0"/>
        <axis xyz="0 0 1"/>
    </joint>
    <link name="left_wheel">
        <visual>
            <geometry>
                <cylinder radius="0.06" length="0.05"/>
            </geometry>
            <material name="purple"/>
        </visual>
        <collision>
            <geometry>
                <sphere radius="0.06" />
            </geometry>
        </collision>
        <xacro:inertial_cylinder mass="0.1" length="0.05" radius="0.06">
            <origin xyz="0 0 0" rpy="0 0 0"/>
        </xacro:inertial_cylinder>
    </link>
    <gazebo reference="left_wheel">
        <material>Gazebo/Purple</material>
    </gazebo>


    <!-- right wheels link-->
    <joint name="right_wheel_joint" type="continuous">
        <parent link="base_link"/>
        <child link="right_wheel"/>
        <origin xyz="0 -0.205 0.02" rpy="${pi/2} 0 0"/>
        <axis xyz="0 0 -1"/>
    </joint>
    <link name="right_wheel">
        <visual>
            <geometry>
                <cylinder radius="0.06" length="0.05"/>
            </geometry>
            <material name="purple"/>
        </visual>
        <collision>
            <geometry>
                <sphere radius="0.06" />
            </geometry>
        </collision>
        <xacro:inertial_cylinder mass="0.1" length="0.05" radius="0.06">
            <origin xyz="0 0 0" rpy="0 0 0"/>
        </xacro:inertial_cylinder>
    </link>
    <gazebo reference="right_wheel">
        <material>Gazebo/Purple</material>
    </gazebo>

        <!-- caster wheels link-->
    <joint name="caster_wheel_joint" type="fixed">
        <parent link="chassis"/>
        <child link="caster_wheel"/>
        <origin xyz="-0.22 0 -0.012"/>
    </joint>
    <link name="caster_wheel">
        <visual>
            <geometry>
                <sphere radius="0.03"/>
            </geometry>
            <material name="grey"/>
        </visual>
        <collision>
            <geometry>
                <sphere radius="0.03"/>
            </geometry>
        </collision>
        <xacro:inertial_sphere mass="0.4" radius="0.03">
            <origin xyz="0 0 0" rpy="0 0 0"/>
        </xacro:inertial_sphere>
    </link>
    <gazebo reference="caster_wheel">
        <material>Gazebo/Grey</material>
        <mu1 value="0.001"/>
        <mu2 value="0.001"/>
    </gazebo>






</robot>
